Workbook

Sheet Финальная анкета
A1: ДЫМОВ 25. 100 ШАГОВ НА ПУТИ К УСПЕХУ — ОФИС / ФИНАЛЬНАЯ ВЕРСИЯ
A2: Ровно 100 определений вопросов. Корпоративный блок сохранён полностью. Добавлены площадка, ИИ и финальные вопросы доверия. Ориентир для сайта: около 25 минут.
A3: Важно: вопрос о городе/площадке используется только для агрегированного анализа; отдельные срезы по малым группам не публиковать. Рекомендуемый порог анонимности — не менее 10 ответов на группу.
A5: № | B5: ID сайта | C5: Блок | D5: Подблок | E5: Вопрос | F5: Тип ответа | G5: Варианты ответа | H5: Обязательный | I5: Условие показа | J5: Исходный Q / статус
A6: 1 | B6: OFF_Q001 | C6: eNPS | E6: Насколько вероятно, что вы порекомендуете «Дымов» знакомому как хорошее место работы? | F6: Шкала 0–10 | G6: 0; 1; 2; 3; 4; 5; 6; 7; 8; 9; 10 | H6: Да | I6: Всем | J6: 1 / Сохранён
A7: 2 | B7: OFF_Q002 | C7: Вовлечённость | E7: Я понимаю, какого результата от меня ожидают. | F7: Шкала 1–5 | G7: 1 — полностью не согласен; 5 — полностью согласен | H7: Да | I7: Всем | J7: 2 / Сохранён
A8: 3 | B8: OFF_Q003 | C8: Вовлечённость | E8: Я понимаю, как моя работа влияет на общий результат компании. | F8: Шкала 1–5 | G8: 1 — полностью не согласен; 5 — полностью согласен | H8: Да | I8: Всем | J8: 3 / Сохранён
A9: 4 | B9: OFF_Q006 | C9: Вовлечённость | E9: Я могу проявлять инициативу и предлагать новые решения. | F9: Шкала 1–5 | G9: 1 — полностью не согласен; 5 — полностью согласен | H9: Да | I9: Всем | J9: 6 / Сохранён
A10: 5 | B10: OFF_Q007 | C10: Вовлечённость | E10: Я горжусь тем, что работаю в «Дымов». | F10: Шкала 1–5 | G10: 1 — полностью не согласен; 5 — полностью согласен | H10: Да | I10: Всем | J10: 7 / Сохранён
A11: 6 | B11: OFF_Q008 | C11: Вовлечённость | E11: Среда в компании мотивирует меня достигать результата выше формально ожидаемого. | F11: Шкала 1–5 | G11: 1 — полностью не согласен; 5 — полностью согласен | H11: Да | I11: Всем | J11: 8 / Сохранён
A12: 7 | B12: OFF_Q009 | C12: Вовлечённость | E12: Я регулярно вижу конкретный результат своей работы. | F12: Шкала 1–5 | G12: 1 — полностью не согласен; 5 — полностью согласен | H12: Да | I12: Всем | J12: 9 / Сохранён
A13: 8 | B13: OFF_Q011 | C13: Вовлечённость | E13: Я понимаю, по каким признакам могу оценить, что хорошо справляюсь со своей работой. | F13: Шкала 1–5 | G13: 1 — полностью не согласен; 5 — полностью согласен | H13: Да | I13: Всем | J13: 11 / Сохранён
A14: 9 | B14: OFF_Q012 | C14: Вовлечённость | E14: Что чаще всего мешает вам чувствовать результат и завершённость своей работы и что помогло бы это изменить? | F14: Длинный текст | H14: Нет | I14: Всем | J14: 12 / Объединён / уточнён
A15: 10 | B15: OFF_Q016 | C15: Эффективность | E15: Я понимаю, куда обратиться, если сталкиваюсь с повторяющейся рабочей проблемой. | F15: Шкала 1–5 | G15: 1 — полностью не согласен; 5 — полностью согласен | H15: Да | I15: Всем | J15: 16 / Сохранён
A16: 11 | B16: OFF_Q017 | C16: Эффективность | E16: Если я озвучиваю проблему или предложение, я понимаю, что с ним происходит дальше. | F16: Шкала 1–5 | G16: 1 — полностью не согласен; 5 — полностью согласен | H16: Да | I16: Всем | J16: 17 / Сохранён
A17: 12 | B17: OFF_Q018 | C17: Эффективность | E17: Мне не приходится регулярно выполнять лишние ручные действия из-за ограничений рабочих систем. | F17: Шкала 1–5 | G17: 1 — полностью не согласен; 5 — полностью согласен | H17: Да | I17: Всем | J17: 18 / Сохранён
A18: 13 | B18: OFF_Q019 | C18: Эффективность | E18: У меня есть все необходимые доступы к системам и информации для выполнения моей работы. | F18: Шкала 1–5 | G18: 1 — полностью не согласен; 5 — полностью согласен | H18: Да | I18: Всем | J18: 19 / Сохранён
A19: 14 | B19: OFF_Q020 | C19: Эффективность | E19: Если возникает техническая проблема, я понимаю, куда обратиться и могу получить решение в приемлемый срок. | F19: Шкала 1–5 | G19: 1 — полностью не согласен; 5 — полностью согласен | H19: Да | I19: Всем | J19: 20 / Сохранён
A20: 15 | B20: OFF_AI_01 | C20: Эффективность | D20: ИИ и рабочие инструменты | E20: Используете ли вы инструменты искусственного интеллекта в своей работе? | F20: Один вариант | G20: Да, регулярно; Да, время от времени; Пробовал(а), но практически не использую; Нет, не использую | H20: Да | I20: Всем | J20: NEW / Новый
A21: 16 | B21: OFF_AI_02 | C21: Эффективность | D21: ИИ и рабочие инструменты | E21: Какими инструментами ИИ вы пользуетесь в работе? Выберите все подходящие варианты. | F21: Несколько вариантов | G21: ChatGPT; Microsoft Copilot; Gemini; Claude; Perplexity; GigaChat; YandexGPT; Другой | H21: Да | I21: Если OFF_AI_01 = «Да, регулярно» или «Да, время от времени» | J21: NEW / Новый
A22: 17 | B22: OFF_AI_03 | C22: Эффективность | D22: ИИ и рабочие инструменты | E22: Какой версией или типом доступа к ИИ-инструментам вы преимущественно пользуетесь? | F22: Один вариант | G22: Бесплатная версия; Личная платная версия; Оплачивает компания / корпоративный доступ; Использую и бесплатные, и платные версии; Не знаю; Другое | H22: Да | I22: Если OFF_AI_01 = «Да, регулярно» или «Да, время от времени» | J22: NEW / Новый
A23: 18 | B23: OFF_AI_05 | C23: Эффективность | D23: ИИ и рабочие инструменты | E23: В каких рабочих задачах ИИ приносит вам наибольшую пользу? | F23: Длинный текст | H23: Нет | I23: Если OFF_AI_01 = «Да, регулярно» или «Да, время от времени» | J23: NEW / Новый
A24: 19 | B24: OFF_AI_06 | C24: Эффективность | D24: ИИ и рабочие инструменты | E24: Могли бы инструменты ИИ быть полезны вам в работе? | F24: Один вариант | G24: Да; Скорее да; Скорее нет; Нет; Не знаю, как их можно применить в моей работе | H24: Да | I24: Если OFF_AI_01 = «Пробовал(а), но практически не использую» или «Нет, не использую» | J24: NEW / Новый
A25: 20 | B25: OFF_AI_07 | C25: Эффективность | D25: ИИ и рабочие инструменты | E25: Как вы могли бы применять ИИ в своей работе? | F25: Длинный текст | H25: Нет | I25: Если OFF_AI_01 = «Пробовал(а), но практически не использую» или «Нет, не использую» | J25: NEW / Новый
A26: 21 | B26: OFF_AI_08 | C26: Эффективность | D26: ИИ и рабочие инструменты | E26: Что сегодня мешает вам эффективнее использовать ИИ в работе? Выберите все подходящие варианты. | F26: Несколько вариантов | G26: У меня нет доступа к оплачиваемой версии; Не знаю, какие инструменты подходят; Не понимаю, для каких задач можно использовать ИИ; Не хватает знаний / навыков; Нужно обучение; Нет корпоративного доступа; Есть ограничения по работе с корпоративными / конфиденциальными данными; Не доверяю качеству ответов; Не понимаю, какие данные можно передавать ИИ; В моей работе ИИ не требуется; Ничего не мешает; Другое | H26: Да | I26: Всем | J26: NEW / Новый
A27: 22 | B27: OFF_AI_09 | C27: Эффективность | D27: ИИ и рабочие инструменты | E27: Что помогло бы вам эффективнее использовать ИИ в работе? Выберите все подходящие варианты. | F27: Несколько вариантов | G27: Доступ к платной версии; Корпоративный доступ; Базовое обучение; Обучение под задачи моей функции; Примеры и готовые сценарии использования; Понятные правила компании по работе с ИИ и данными; Консультация специалиста; Ничего не требуется; Другое | H27: Да | I27: Всем | J27: NEW / Новый
A28: 23 | B28: OFF_Q021 | C28: Эффективность | E28: Какая программа, система или рабочий процесс сегодня отнимает у вас лишнее время и что в нём необходимо изменить или автоматизировать? | F28: Длинный текст | H28: Нет | I28: Всем | J28: 21 / Объединён / уточнён
A29: 24 | B29: OFF_Q023 | C29: Эффективность | E29: Проблемы, которые регулярно повторяются, в конечном итоге устраняются, а не только решаются каждый раз вручную. | F29: Шкала 1–5 | G29: 1 — полностью не согласен; 5 — полностью согласен | H29: Да | I29: Всем | J29: 23 / Сохранён
A30: 25 | B30: OFF_Q024 | C30: Эффективность | E30: Компания достаточно быстро реагирует на проблемы, которые мешают работе сотрудников. | F30: Шкала 1–5 | G30: 1 — полностью не согласен; 5 — полностью согласен | H30: Да | I30: Всем | J30: 24 / Сохранён
A31: 26 | B31: OFF_Q025 | C31: Эффективность | E31: Какой процесс в компании, на ваш взгляд, давно необходимо изменить или упростить? | F31: Длинный текст | H31: Нет | I31: Всем | J31: 25 / Сохранён
A32: 27 | B32: OFF_Q026 | C32: Эффективность | E32: Как часто вам приходится выполнять рабочие задачи за пределами установленного рабочего времени? | F32: Один вариант | G32: Никогда; Редко; Иногда; Часто; Практически постоянно | H32: Да | I32: Всем | J32: 26 / Сохранён
A33: 28 | B33: OFF_Q027 | C33: Эффективность | E33: Рабочие задачи обычно позволяют мне сохранять достаточно времени для личной жизни и отдыха. | F33: Шкала 1–5 | G33: 1 — полностью не согласен; 5 — полностью согласен | H33: Да | I33: Всем | J33: 27 / Сохранён
A34: 29 | B34: OFF_Q029 | C34: Эффективность | E34: После окончания рабочего дня я могу действительно отключиться от рабочих вопросов. | F34: Шкала 1–5 | G34: 1 — полностью не согласен; 5 — полностью согласен | H34: Да | I34: Всем | J34: 29 / Сохранён
A35: 30 | B35: OFF_Q031 | C35: Руководитель | E35: Мой руководитель понятно ставит задачи и приоритеты. | F35: Шкала 1–5 | G35: 1 — полностью не согласен; 5 — полностью согласен | H35: Да | I35: Всем | J35: 31 / Сохранён
A36: 31 | B36: OFF_Q032 | C36: Руководитель | E36: Руководитель относится ко мне уважительно. | F36: Шкала 1–5 | G36: 1 — полностью не согласен; 5 — полностью согласен | H36: Да | I36: Всем | J36: 32 / Сохранён
A37: 32 | B37: OFF_Q033 | C37: Руководитель | E37: Я считаю, что руководитель справедливо оценивает мою работу и вклад. | F37: Шкала 1–5 | G37: 1 — полностью не согласен; 5 — полностью согласен | H37: Да | I37: Всем | J37: 33 / Сохранён
A38: 33 | B38: OFF_Q034 | C38: Руководитель | E38: Я регулярно получаю полезную обратную связь. | F38: Шкала 1–5 | G38: 1 — полностью не согласен; 5 — полностью согласен | H38: Да | I38: Всем | J38: 34 / Сохранён
A39: 34 | B39: OFF_Q035 | C39: Руководитель | E39: Я могу открыто говорить руководителю о проблемах и предлагать идеи. | F39: Шкала 1–5 | G39: 1 — полностью не согласен; 5 — полностью согласен | H39: Да | I39: Всем | J39: 35 / Сохранён
A40: 35 | B40: OFF_Q037 | C40: Руководитель | E40: Я считаю, что основные правила и требования применяются к сотрудникам последовательно и одинаково. | F40: Шкала 1–5 | G40: 1 — полностью не согласен; 5 — полностью согласен | H40: Да | I40: Всем | J40: 37 / Сохранён
A41: 36 | B41: OFF_Q038 | C41: Руководитель | E41: В моём подразделении рабочая нагрузка и ответственность распределяются справедливо. | F41: Шкала 1–5 | G41: 1 — полностью не согласен; 5 — полностью согласен | H41: Да | I41: Всем | J41: 38 / Сохранён
...

Sheet Сводка
A1: ИТОГ: «100 ШАГОВ НА ПУТИ К УСПЕХУ»
A2: В финальной структуре ровно 100 определений вопросов. Из-за ветвления ИИ сотрудник увидит 97–98 экранов. Ориентир прохождения: около 25 минут.
A4: Блок | B4: Вопросов в таблице | C4: Открытых вопросов | D4: Обязательных | E4: Комментарий | F4: Статус
A5: eNPS | B5: =COUNTIF('Финальная анкета'!$C:$C,A5) | C5: =COUNTIFS('Финальная анкета'!$C:$C,A5,'Финальная анкета'!$F:$F,"*текст*") | D5: =COUNTIFS('Финальная анкета'!$C:$C,A5,'Финальная анкета'!$H:$H,"Да") | E5: Ключевой outcome-показатель. | F5: Оптимизирован
A6: Вовлечённость | B6: =COUNTIF('Финальная анкета'!$C:$C,A6) | C6: =COUNTIFS('Финальная анкета'!$C:$C,A6,'Финальная анкета'!$F:$F,"*текст*") | D6: =COUNTIFS('Финальная анкета'!$C:$C,A6,'Финальная анкета'!$H:$H,"Да") | E6: Сокращено; оставлены ключевые драйверы и один открытый вопрос. | F6: Оптимизирован
A7: Эффективность | B7: =COUNTIF('Финальная анкета'!$C:$C,A7) | C7: =COUNTIFS('Финальная анкета'!$C:$C,A7,'Финальная анкета'!$F:$F,"*текст*") | D7: =COUNTIFS('Финальная анкета'!$C:$C,A7,'Финальная анкета'!$H:$H,"Да") | E7: Включает технологии, процессы, work-life balance и условный блок ИИ. | F7: Оптимизирован
A8: Руководитель | B8: =COUNTIF('Финальная анкета'!$C:$C,A8) | C8: =COUNTIFS('Финальная анкета'!$C:$C,A8,'Финальная анкета'!$F:$F,"*текст*") | D8: =COUNTIFS('Финальная анкета'!$C:$C,A8,'Финальная анкета'!$H:$H,"Да") | E8: Оставлены постановка задач, уважение, обратная связь и справедливость. | F8: Оптимизирован
A9: Самостоятельность | B9: =COUNTIF('Финальная анкета'!$C:$C,A9) | C9: =COUNTIFS('Финальная анкета'!$C:$C,A9,'Финальная анкета'!$F:$F,"*текст*") | D9: =COUNTIFS('Финальная анкета'!$C:$C,A9,'Финальная анкета'!$H:$H,"Да") | E9: Сохранён полностью. | F9: Сохранён полностью
A10: Топ-менеджмент | B10: =COUNTIF('Финальная анкета'!$C:$C,A10) | C10: =COUNTIFS('Финальная анкета'!$C:$C,A10,'Финальная анкета'!$F:$F,"*текст*") | D10: =COUNTIFS('Финальная анкета'!$C:$C,A10,'Финальная анкета'!$H:$H,"Да") | E10: Сокращено до конкретных вопросов + одного открытого. | F10: Оптимизирован
A11: Признание | B11: =COUNTIF('Финальная анкета'!$C:$C,A11) | C11: =COUNTIFS('Финальная анкета'!$C:$C,A11,'Финальная анкета'!$F:$F,"*текст*") | D11: =COUNTIFS('Финальная анкета'!$C:$C,A11,'Финальная анкета'!$H:$H,"Да") | E11: Оставлен личный опыт признания и предпочитаемые формы. | F11: Оптимизирован
A12: Намерение продолжать работу в компании | B12: =COUNTIF('Финальная анкета'!$C:$C,A12) | C12: =COUNTIFS('Финальная анкета'!$C:$C,A12,'Финальная анкета'!$F:$F,"*текст*") | D12: =COUNTIFS('Финальная анкета'!$C:$C,A12,'Финальная анкета'!$H:$H,"Да") | E12: Оставлены 12 месяцев и реальный риск ухода. | F12: Оптимизирован
A13: Развитие и карьера | B13: =COUNTIF('Финальная анкета'!$C:$C,A13) | C13: =COUNTIFS('Финальная анкета'!$C:$C,A13,'Финальная анкета'!$F:$F,"*текст*") | D13: =COUNTIFS('Финальная анкета'!$C:$C,A13,'Финальная анкета'!$H:$H,"Да") | E13: Оставлены развитие экспертизы и карьерные перспективы. | F13: Оптимизирован
A14: Приоритеты | B14: =COUNTIF('Финальная анкета'!$C:$C,A14) | C14: =COUNTIFS('Финальная анкета'!$C:$C,A14,'Финальная анкета'!$F:$F,"*текст*") | D14: =COUNTIFS('Финальная анкета'!$C:$C,A14,'Финальная анкета'!$H:$H,"Да") | E14: Сохранён TOP-факторов результативности. | F14: Оптимизирован
A15: Климат | B15: =COUNTIF('Финальная анкета'!$C:$C,A15) | C15: =COUNTIFS('Финальная анкета'!$C:$C,A15,'Финальная анкета'!$F:$F,"*текст*") | D15: =COUNTIFS('Финальная анкета'!$C:$C,A15,'Финальная анкета'!$H:$H,"Да") | E15: Сохранено ядро командной и психологической безопасности. | F15: Оптимизирован
A16: Условия | B16: =COUNTIF('Финальная анкета'!$C:$C,A16) | C16: =COUNTIFS('Финальная анкета'!$C:$C,A16,'Финальная анкета'!$F:$F,"*текст*") | D16: =COUNTIFS('Финальная анкета'!$C:$C,A16,'Финальная анкета'!$H:$H,"Да") | E16: Добавлена площадка; отдельный шум/кофе/еда/зона отдыха сведены в приоритеты. | F16: Оптимизирован
... A23: Финал | B23: =COUNTIF('Финальная анкета'!$C:$C,A23) | C23: =COUNTIFS('Финальная анкета'!$C:$C,A23,'Финальная анкета'!$F:$F,"*текст*") | D23: =COUNTIFS('Финальная анкета'!$C:$C,A23,'Финальная анкета'!$H:$H,"Да") | E23: Финальный открытый вопрос + 3 вопроса доверия. | F23: Дополнен
A24: ИТОГО определений вопросов | B24: =SUM(B5:B23) | C24: =SUM(C5:C23) | D24: =SUM(D5:D23)
A26: Маршрут сотрудника: 88 сохранённых вопросов из исходной анкеты + 1 площадка + 3 доверия + 4–6 вопросов ИИ по ветке = 97–98 экранов. В таблице ИИ описан 8 строками, потому что две ветки взаимоисключающие.
A27: Время: быстро ≈15–18 мин; нормальное вдумчивое прохождение ≈20–25 мин; с подробными открытыми комментариями ≈25–30 мин. Для сайта рекомендуется писать «около 25 минут».

Sheet Удалено
A1: ВОПРОСЫ, ИСКЛЮЧЁННЫЕ ИЗ ФИНАЛЬНОЙ ВЕРСИИ
A3: Исходный Q | B3: Блок | C3: Вопрос | D3: Причина удаления | E3: Решение
A4: 4 | B4: Вовлечённость | C4: У меня есть необходимые ресурсы и условия, чтобы хорошо выполнять свою работу. | D4: Общий вопрос; ресурсы и условия измеряются подробнее в блоках «Эффективность» и «Условия». | E4: Удалить из основной офисной анкеты
A5: 5 | B5: Вовлечённость | C5: Я чувствую, что мой вклад в компании имеет значение. | D5: Смысловой дубль влияния на общий результат и признания вклада. | E5: Удалить из основной офисной анкеты
A6: 10 | B6: Вовлечённость | C6: В конце рабочего дня / недели у меня обычно есть ощущение, что важные задачи действительно продвинулись или завершены. | D6: Смысловой дубль ощущения конкретного результата; оставлены Q9 и Q11. | E6: Удалить из основной офисной анкеты
A7: 13 | B7: Вовлечённость | C7: Что, на ваш взгляд, помогло бы изменить эту ситуацию? | D7: Объединён с Q12 в один открытый вопрос. | E7: Удалить из основной офисной анкеты
A8: 14 | B8: Эффективность | C8: Мне хватает рабочего времени для выполнения основного объёма задач. | D8: Заменён более фактическими вопросами о работе вне рабочего времени и балансе. | E8: Удалить из основной офисной анкеты
A9: 15 | B9: Эффективность | C9: Существующие процессы помогают выполнять работу, а не создают лишние препятствия. | D9: Слишком общий; процессы измеряются конкретными вопросами Q16–Q24. | E9: Удалить из основной офисной анкеты
A10: 22 | B10: Эффективность | C10: Что конкретно необходимо изменить или автоматизировать? | D10: Объединён с Q21 в один открытый вопрос про систему/процесс и нужное изменение. | E10: Удалить из основной офисной анкеты
A11: 28 | B11: Эффективность | C11: Срочные рабочие вопросы редко требуют от меня менять личные планы или заниматься работой в свободное время. | D11: Дублирует частоту работы вне рабочего времени и возможность отключаться после работы. | E11: Удалить из основной офисной анкеты
A12: 30 | B12: Эффективность | C12: Что в организации работы сильнее всего мешает вам сохранять нормальный баланс между работой и личным временем? | D12: Открытый дубль блока work-life balance; причины видны через другие вопросы. | E12: Удалить из основной офисной анкеты
A13: 36 | B13: Руководитель | C13: Что руководителям компании стоит изменить, чтобы сотрудникам было проще достигать максимального результата? | D13: Слишком общий открытый вопрос; остаются конкретные оценки руководителя и справедливости. | E13: Удалить из основной офисной анкеты
A14: 42 | B14: Топ-менеджмент | C14: Стратегические решения высшего руководства дают понятный ориентир для моей функции. | D14: Более общий стратегический вопрос; оставлен конкретный Q44 о связи целей. | E14: Удалить из основной офисной анкеты
A15: 48 | B15: Топ-менеджмент | C15: Что высшему руководству стоило бы изменить в коммуникации с сотрудниками? | D15: Объединён с Q47 в один открытый вопрос о нехватке информации и коммуникации. | E15: Удалить из основной офисной анкеты
... A43: 127 | B43: Развитие | C43: Что нового вы хотели бы видеть в условиях работы и жизни сотрудников компании? | D43: Общий wishlist дублирует финальный Q128 с приоритизацией изменений. | E43: Удалить из основной офисной анкеты
A44: AI-04 | B44: Эффективность / ИИ и рабочие инструменты | C44: Как вы используете ИИ в своей работе? | D44: Слишком общий открытый вопрос; более содержательный вопрос о конкретных рабочих задачах и пользе ИИ остаётся. | E44: Удалить, чтобы финальная структура содержала ровно 100 вопросов
